2025-04-10 16:43:19,936 INFO    MainThread:3628795 [wandb_setup.py:_flush():67] Current SDK version is 0.19.9
2025-04-10 16:43:19,937 INFO    MainThread:3628795 [wandb_setup.py:_flush():67] Configure stats pid to 3628795
2025-04-10 16:43:19,937 INFO    MainThread:3628795 [wandb_setup.py:_flush():67] Loading settings from /home/mila/x/xut/.config/wandb/settings
2025-04-10 16:43:19,937 INFO    MainThread:3628795 [wandb_setup.py:_flush():67] Loading settings from /home/mila/x/xut/github/Comp579Text-based-adventure-games-using-SAC/src/wandb/settings
2025-04-10 16:43:19,937 INFO    MainThread:3628795 [wandb_setup.py:_flush():67] Loading settings from environment variables
2025-04-10 16:43:19,937 INFO    MainThread:3628795 [wandb_init.py:setup_run_log_directory():662] Logging user logs to /home/mila/x/xut/github/Comp579Text-based-adventure-games-using-SAC/src/wandb/run-20250410_164319-hmpmnsl9/logs/debug.log
2025-04-10 16:43:19,937 INFO    MainThread:3628795 [wandb_init.py:setup_run_log_directory():663] Logging internal logs to /home/mila/x/xut/github/Comp579Text-based-adventure-games-using-SAC/src/wandb/run-20250410_164319-hmpmnsl9/logs/debug-internal.log
2025-04-10 16:43:19,937 INFO    MainThread:3628795 [wandb_init.py:init():781] calling init triggers
2025-04-10 16:43:19,937 INFO    MainThread:3628795 [wandb_init.py:init():786] wandb.init called with sweep_config: {}
config: {'output_dir': 'output', 'rom_path': 'z-machine-games-master/jericho-game-suite/905.z5', 'env_name': 'game_name', 'spm_path': 'unigram_8k.model', 'env_step_limit': 100, 'seed': 0, 'num_envs': 8, 'max_steps': 10000, 'update_freq': 1, 'checkpoint_freq': 5000, 'log_freq': 100, 'memory_size': 100000, 'batch_size': 32, 'gamma': 0.9, 'learning_rate': 0.0001, 'clip': 5, 'embedding_dim': 128, 'hidden_dim': 128, 'load_checkpoint': '', 'rnd_scale': 0.3, 'reward_shaping': True, 'tensorboard': 0, 'wandb': 1, 'wandb_project': 'comp_579', 'wandb_group': '', 'agent_type': 'SAC', 'sample_strat': 'uniform', '_wandb': {}}
2025-04-10 16:43:19,937 INFO    MainThread:3628795 [wandb_init.py:init():809] starting backend
2025-04-10 16:43:19,938 INFO    MainThread:3628795 [wandb_init.py:init():813] sending inform_init request
2025-04-10 16:43:19,949 INFO    MainThread:3628795 [backend.py:_multiprocessing_setup():101] multiprocessing start_methods=fork,spawn,forkserver, using: spawn
2025-04-10 16:43:19,949 INFO    MainThread:3628795 [wandb_init.py:init():823] backend started and connected
2025-04-10 16:43:19,951 INFO    MainThread:3628795 [wandb_init.py:init():915] updated telemetry
2025-04-10 16:43:19,969 INFO    MainThread:3628795 [wandb_init.py:init():939] communicating run to backend with 90.0 second timeout
2025-04-10 16:43:20,391 INFO    MainThread:3628795 [wandb_init.py:init():1014] starting run threads in backend
2025-04-10 16:43:20,534 INFO    MainThread:3628795 [wandb_run.py:_console_start():2454] atexit reg
2025-04-10 16:43:20,534 INFO    MainThread:3628795 [wandb_run.py:_redirect():2306] redirect: wrap_raw
2025-04-10 16:43:20,534 INFO    MainThread:3628795 [wandb_run.py:_redirect():2371] Wrapping output streams.
2025-04-10 16:43:20,534 INFO    MainThread:3628795 [wandb_run.py:_redirect():2394] Redirects installed.
2025-04-10 16:43:20,537 INFO    MainThread:3628795 [wandb_init.py:init():1056] run started, returning control to user process
2025-04-10 16:43:41,536 INFO    MsgRouterThr:3628795 [mailbox.py:close():129] [no run ID] Closing mailbox, abandoning 1 handles.
2025-04-10 16:43:41,860 ERROR   MainThread:3628795 [redirect.py:_on_write():661] [no run ID] error in stderr callback
Traceback (most recent call last):
  File "/home/mila/x/xut/.conda/envs/rl_venv/lib/python3.10/site-packages/wandb/sdk/lib/redirect.py", line 659, in _on_write
    cb(written_data)
  File "/home/mila/x/xut/.conda/envs/rl_venv/lib/python3.10/site-packages/wandb/sdk/wandb_run.py", line 2381, in <lambda>
    lambda data: self._console_raw_callback("stderr", data),
  File "/home/mila/x/xut/.conda/envs/rl_venv/lib/python3.10/site-packages/wandb/sdk/wandb_run.py", line 387, in wrapper
    return func(self, *args, **kwargs)
  File "/home/mila/x/xut/.conda/envs/rl_venv/lib/python3.10/site-packages/wandb/sdk/wandb_run.py", line 435, in wrapper_fn
    return func(self, *args, **kwargs)
  File "/home/mila/x/xut/.conda/envs/rl_venv/lib/python3.10/site-packages/wandb/sdk/wandb_run.py", line 1518, in _console_raw_callback
    self._backend.interface.publish_output_raw(name, data)
  File "/home/mila/x/xut/.conda/envs/rl_venv/lib/python3.10/site-packages/wandb/sdk/interface/interface.py", line 761, in publish_output_raw
    self._publish_output_raw(o)
  File "/home/mila/x/xut/.conda/envs/rl_venv/lib/python3.10/site-packages/wandb/sdk/interface/interface_shared.py", line 38, in _publish_output_raw
    self._publish(rec)
  File "/home/mila/x/xut/.conda/envs/rl_venv/lib/python3.10/site-packages/wandb/sdk/interface/interface_sock.py", line 39, in _publish
    self._sock_client.send_record_publish(record)
  File "/home/mila/x/xut/.conda/envs/rl_venv/lib/python3.10/site-packages/wandb/sdk/lib/sock_client.py", line 174, in send_record_publish
    self.send_server_request(server_req)
  File "/home/mila/x/xut/.conda/envs/rl_venv/lib/python3.10/site-packages/wandb/sdk/lib/sock_client.py", line 154, in send_server_request
    self._send_message(msg)
  File "/home/mila/x/xut/.conda/envs/rl_venv/lib/python3.10/site-packages/wandb/sdk/lib/sock_client.py", line 151, in _send_message
    self._sendall_with_error_handle(header + data)
  File "/home/mila/x/xut/.conda/envs/rl_venv/lib/python3.10/site-packages/wandb/sdk/lib/sock_client.py", line 130, in _sendall_with_error_handle
    sent = self._sock.send(data)
BrokenPipeError: [Errno 32] Broken pipe
2025-04-10 16:43:41,866 ERROR   MainThread:3628795 [redirect.py:_on_write():661] [no run ID] error in stderr callback
Traceback (most recent call last):
  File "/home/mila/x/xut/.conda/envs/rl_venv/lib/python3.10/site-packages/wandb/sdk/lib/redirect.py", line 659, in _on_write
    cb(written_data)
  File "/home/mila/x/xut/.conda/envs/rl_venv/lib/python3.10/site-packages/wandb/sdk/wandb_run.py", line 2381, in <lambda>
    lambda data: self._console_raw_callback("stderr", data),
  File "/home/mila/x/xut/.conda/envs/rl_venv/lib/python3.10/site-packages/wandb/sdk/wandb_run.py", line 387, in wrapper
    return func(self, *args, **kwargs)
  File "/home/mila/x/xut/.conda/envs/rl_venv/lib/python3.10/site-packages/wandb/sdk/wandb_run.py", line 435, in wrapper_fn
    return func(self, *args, **kwargs)
  File "/home/mila/x/xut/.conda/envs/rl_venv/lib/python3.10/site-packages/wandb/sdk/wandb_run.py", line 1518, in _console_raw_callback
    self._backend.interface.publish_output_raw(name, data)
  File "/home/mila/x/xut/.conda/envs/rl_venv/lib/python3.10/site-packages/wandb/sdk/interface/interface.py", line 761, in publish_output_raw
    self._publish_output_raw(o)
  File "/home/mila/x/xut/.conda/envs/rl_venv/lib/python3.10/site-packages/wandb/sdk/interface/interface_shared.py", line 38, in _publish_output_raw
    self._publish(rec)
  File "/home/mila/x/xut/.conda/envs/rl_venv/lib/python3.10/site-packages/wandb/sdk/interface/interface_sock.py", line 39, in _publish
    self._sock_client.send_record_publish(record)
  File "/home/mila/x/xut/.conda/envs/rl_venv/lib/python3.10/site-packages/wandb/sdk/lib/sock_client.py", line 174, in send_record_publish
    self.send_server_request(server_req)
  File "/home/mila/x/xut/.conda/envs/rl_venv/lib/python3.10/site-packages/wandb/sdk/lib/sock_client.py", line 154, in send_server_request
    self._send_message(msg)
  File "/home/mila/x/xut/.conda/envs/rl_venv/lib/python3.10/site-packages/wandb/sdk/lib/sock_client.py", line 151, in _send_message
    self._sendall_with_error_handle(header + data)
  File "/home/mila/x/xut/.conda/envs/rl_venv/lib/python3.10/site-packages/wandb/sdk/lib/sock_client.py", line 130, in _sendall_with_error_handle
    sent = self._sock.send(data)
BrokenPipeError: [Errno 32] Broken pipe
2025-04-10 16:43:41,866 ERROR   MainThread:3628795 [redirect.py:_on_write():661] [no run ID] error in stderr callback
Traceback (most recent call last):
  File "/home/mila/x/xut/.conda/envs/rl_venv/lib/python3.10/site-packages/wandb/sdk/lib/redirect.py", line 659, in _on_write
    cb(written_data)
  File "/home/mila/x/xut/.conda/envs/rl_venv/lib/python3.10/site-packages/wandb/sdk/wandb_run.py", line 2381, in <lambda>
    lambda data: self._console_raw_callback("stderr", data),
  File "/home/mila/x/xut/.conda/envs/rl_venv/lib/python3.10/site-packages/wandb/sdk/wandb_run.py", line 387, in wrapper
    return func(self, *args, **kwargs)
  File "/home/mila/x/xut/.conda/envs/rl_venv/lib/python3.10/site-packages/wandb/sdk/wandb_run.py", line 435, in wrapper_fn
    return func(self, *args, **kwargs)
  File "/home/mila/x/xut/.conda/envs/rl_venv/lib/python3.10/site-packages/wandb/sdk/wandb_run.py", line 1518, in _console_raw_callback
    self._backend.interface.publish_output_raw(name, data)
  File "/home/mila/x/xut/.conda/envs/rl_venv/lib/python3.10/site-packages/wandb/sdk/interface/interface.py", line 761, in publish_output_raw
    self._publish_output_raw(o)
  File "/home/mila/x/xut/.conda/envs/rl_venv/lib/python3.10/site-packages/wandb/sdk/interface/interface_shared.py", line 38, in _publish_output_raw
    self._publish(rec)
  File "/home/mila/x/xut/.conda/envs/rl_venv/lib/python3.10/site-packages/wandb/sdk/interface/interface_sock.py", line 39, in _publish
    self._sock_client.send_record_publish(record)
  File "/home/mila/x/xut/.conda/envs/rl_venv/lib/python3.10/site-packages/wandb/sdk/lib/sock_client.py", line 174, in send_record_publish
    self.send_server_request(server_req)
  File "/home/mila/x/xut/.conda/envs/rl_venv/lib/python3.10/site-packages/wandb/sdk/lib/sock_client.py", line 154, in send_server_request
    self._send_message(msg)
  File "/home/mila/x/xut/.conda/envs/rl_venv/lib/python3.10/site-packages/wandb/sdk/lib/sock_client.py", line 151, in _send_message
    self._sendall_with_error_handle(header + data)
  File "/home/mila/x/xut/.conda/envs/rl_venv/lib/python3.10/site-packages/wandb/sdk/lib/sock_client.py", line 130, in _sendall_with_error_handle
    sent = self._sock.send(data)
BrokenPipeError: [Errno 32] Broken pipe
2025-04-10 16:43:41,867 ERROR   MainThread:3628795 [redirect.py:_on_write():661] [no run ID] error in stderr callback
Traceback (most recent call last):
  File "/home/mila/x/xut/.conda/envs/rl_venv/lib/python3.10/site-packages/wandb/sdk/lib/redirect.py", line 659, in _on_write
    cb(written_data)
  File "/home/mila/x/xut/.conda/envs/rl_venv/lib/python3.10/site-packages/wandb/sdk/wandb_run.py", line 2381, in <lambda>
    lambda data: self._console_raw_callback("stderr", data),
  File "/home/mila/x/xut/.conda/envs/rl_venv/lib/python3.10/site-packages/wandb/sdk/wandb_run.py", line 387, in wrapper
    return func(self, *args, **kwargs)
  File "/home/mila/x/xut/.conda/envs/rl_venv/lib/python3.10/site-packages/wandb/sdk/wandb_run.py", line 435, in wrapper_fn
    return func(self, *args, **kwargs)
  File "/home/mila/x/xut/.conda/envs/rl_venv/lib/python3.10/site-packages/wandb/sdk/wandb_run.py", line 1518, in _console_raw_callback
    self._backend.interface.publish_output_raw(name, data)
  File "/home/mila/x/xut/.conda/envs/rl_venv/lib/python3.10/site-packages/wandb/sdk/interface/interface.py", line 761, in publish_output_raw
    self._publish_output_raw(o)
  File "/home/mila/x/xut/.conda/envs/rl_venv/lib/python3.10/site-packages/wandb/sdk/interface/interface_shared.py", line 38, in _publish_output_raw
    self._publish(rec)
  File "/home/mila/x/xut/.conda/envs/rl_venv/lib/python3.10/site-packages/wandb/sdk/interface/interface_sock.py", line 39, in _publish
    self._sock_client.send_record_publish(record)
  File "/home/mila/x/xut/.conda/envs/rl_venv/lib/python3.10/site-packages/wandb/sdk/lib/sock_client.py", line 174, in send_record_publish
    self.send_server_request(server_req)
  File "/home/mila/x/xut/.conda/envs/rl_venv/lib/python3.10/site-packages/wandb/sdk/lib/sock_client.py", line 154, in send_server_request
    self._send_message(msg)
  File "/home/mila/x/xut/.conda/envs/rl_venv/lib/python3.10/site-packages/wandb/sdk/lib/sock_client.py", line 151, in _send_message
    self._sendall_with_error_handle(header + data)
  File "/home/mila/x/xut/.conda/envs/rl_venv/lib/python3.10/site-packages/wandb/sdk/lib/sock_client.py", line 130, in _sendall_with_error_handle
    sent = self._sock.send(data)
BrokenPipeError: [Errno 32] Broken pipe
2025-04-10 16:43:41,868 ERROR   MainThread:3628795 [redirect.py:_on_write():661] [no run ID] error in stderr callback
Traceback (most recent call last):
  File "/home/mila/x/xut/.conda/envs/rl_venv/lib/python3.10/site-packages/wandb/sdk/lib/redirect.py", line 659, in _on_write
    cb(written_data)
  File "/home/mila/x/xut/.conda/envs/rl_venv/lib/python3.10/site-packages/wandb/sdk/wandb_run.py", line 2381, in <lambda>
    lambda data: self._console_raw_callback("stderr", data),
  File "/home/mila/x/xut/.conda/envs/rl_venv/lib/python3.10/site-packages/wandb/sdk/wandb_run.py", line 387, in wrapper
    return func(self, *args, **kwargs)
  File "/home/mila/x/xut/.conda/envs/rl_venv/lib/python3.10/site-packages/wandb/sdk/wandb_run.py", line 435, in wrapper_fn
    return func(self, *args, **kwargs)
  File "/home/mila/x/xut/.conda/envs/rl_venv/lib/python3.10/site-packages/wandb/sdk/wandb_run.py", line 1518, in _console_raw_callback
    self._backend.interface.publish_output_raw(name, data)
  File "/home/mila/x/xut/.conda/envs/rl_venv/lib/python3.10/site-packages/wandb/sdk/interface/interface.py", line 761, in publish_output_raw
    self._publish_output_raw(o)
  File "/home/mila/x/xut/.conda/envs/rl_venv/lib/python3.10/site-packages/wandb/sdk/interface/interface_shared.py", line 38, in _publish_output_raw
    self._publish(rec)
  File "/home/mila/x/xut/.conda/envs/rl_venv/lib/python3.10/site-packages/wandb/sdk/interface/interface_sock.py", line 39, in _publish
    self._sock_client.send_record_publish(record)
  File "/home/mila/x/xut/.conda/envs/rl_venv/lib/python3.10/site-packages/wandb/sdk/lib/sock_client.py", line 174, in send_record_publish
    self.send_server_request(server_req)
  File "/home/mila/x/xut/.conda/envs/rl_venv/lib/python3.10/site-packages/wandb/sdk/lib/sock_client.py", line 154, in send_server_request
    self._send_message(msg)
  File "/home/mila/x/xut/.conda/envs/rl_venv/lib/python3.10/site-packages/wandb/sdk/lib/sock_client.py", line 151, in _send_message
    self._sendall_with_error_handle(header + data)
  File "/home/mila/x/xut/.conda/envs/rl_venv/lib/python3.10/site-packages/wandb/sdk/lib/sock_client.py", line 130, in _sendall_with_error_handle
    sent = self._sock.send(data)
BrokenPipeError: [Errno 32] Broken pipe
2025-04-10 16:43:41,869 ERROR   MainThread:3628795 [redirect.py:_on_write():661] [no run ID] error in stderr callback
Traceback (most recent call last):
  File "/home/mila/x/xut/.conda/envs/rl_venv/lib/python3.10/site-packages/wandb/sdk/lib/redirect.py", line 659, in _on_write
    cb(written_data)
  File "/home/mila/x/xut/.conda/envs/rl_venv/lib/python3.10/site-packages/wandb/sdk/wandb_run.py", line 2381, in <lambda>
    lambda data: self._console_raw_callback("stderr", data),
  File "/home/mila/x/xut/.conda/envs/rl_venv/lib/python3.10/site-packages/wandb/sdk/wandb_run.py", line 387, in wrapper
    return func(self, *args, **kwargs)
  File "/home/mila/x/xut/.conda/envs/rl_venv/lib/python3.10/site-packages/wandb/sdk/wandb_run.py", line 435, in wrapper_fn
    return func(self, *args, **kwargs)
  File "/home/mila/x/xut/.conda/envs/rl_venv/lib/python3.10/site-packages/wandb/sdk/wandb_run.py", line 1518, in _console_raw_callback
    self._backend.interface.publish_output_raw(name, data)
  File "/home/mila/x/xut/.conda/envs/rl_venv/lib/python3.10/site-packages/wandb/sdk/interface/interface.py", line 761, in publish_output_raw
    self._publish_output_raw(o)
  File "/home/mila/x/xut/.conda/envs/rl_venv/lib/python3.10/site-packages/wandb/sdk/interface/interface_shared.py", line 38, in _publish_output_raw
    self._publish(rec)
  File "/home/mila/x/xut/.conda/envs/rl_venv/lib/python3.10/site-packages/wandb/sdk/interface/interface_sock.py", line 39, in _publish
    self._sock_client.send_record_publish(record)
  File "/home/mila/x/xut/.conda/envs/rl_venv/lib/python3.10/site-packages/wandb/sdk/lib/sock_client.py", line 174, in send_record_publish
    self.send_server_request(server_req)
  File "/home/mila/x/xut/.conda/envs/rl_venv/lib/python3.10/site-packages/wandb/sdk/lib/sock_client.py", line 154, in send_server_request
    self._send_message(msg)
  File "/home/mila/x/xut/.conda/envs/rl_venv/lib/python3.10/site-packages/wandb/sdk/lib/sock_client.py", line 151, in _send_message
    self._sendall_with_error_handle(header + data)
  File "/home/mila/x/xut/.conda/envs/rl_venv/lib/python3.10/site-packages/wandb/sdk/lib/sock_client.py", line 130, in _sendall_with_error_handle
    sent = self._sock.send(data)
BrokenPipeError: [Errno 32] Broken pipe
2025-04-10 16:43:41,869 ERROR   MainThread:3628795 [redirect.py:_on_write():661] [no run ID] error in stderr callback
Traceback (most recent call last):
  File "/home/mila/x/xut/.conda/envs/rl_venv/lib/python3.10/site-packages/wandb/sdk/lib/redirect.py", line 659, in _on_write
    cb(written_data)
  File "/home/mila/x/xut/.conda/envs/rl_venv/lib/python3.10/site-packages/wandb/sdk/wandb_run.py", line 2381, in <lambda>
    lambda data: self._console_raw_callback("stderr", data),
  File "/home/mila/x/xut/.conda/envs/rl_venv/lib/python3.10/site-packages/wandb/sdk/wandb_run.py", line 387, in wrapper
    return func(self, *args, **kwargs)
  File "/home/mila/x/xut/.conda/envs/rl_venv/lib/python3.10/site-packages/wandb/sdk/wandb_run.py", line 435, in wrapper_fn
    return func(self, *args, **kwargs)
  File "/home/mila/x/xut/.conda/envs/rl_venv/lib/python3.10/site-packages/wandb/sdk/wandb_run.py", line 1518, in _console_raw_callback
    self._backend.interface.publish_output_raw(name, data)
  File "/home/mila/x/xut/.conda/envs/rl_venv/lib/python3.10/site-packages/wandb/sdk/interface/interface.py", line 761, in publish_output_raw
    self._publish_output_raw(o)
  File "/home/mila/x/xut/.conda/envs/rl_venv/lib/python3.10/site-packages/wandb/sdk/interface/interface_shared.py", line 38, in _publish_output_raw
    self._publish(rec)
  File "/home/mila/x/xut/.conda/envs/rl_venv/lib/python3.10/site-packages/wandb/sdk/interface/interface_sock.py", line 39, in _publish
    self._sock_client.send_record_publish(record)
  File "/home/mila/x/xut/.conda/envs/rl_venv/lib/python3.10/site-packages/wandb/sdk/lib/sock_client.py", line 174, in send_record_publish
    self.send_server_request(server_req)
  File "/home/mila/x/xut/.conda/envs/rl_venv/lib/python3.10/site-packages/wandb/sdk/lib/sock_client.py", line 154, in send_server_request
    self._send_message(msg)
  File "/home/mila/x/xut/.conda/envs/rl_venv/lib/python3.10/site-packages/wandb/sdk/lib/sock_client.py", line 151, in _send_message
    self._sendall_with_error_handle(header + data)
  File "/home/mila/x/xut/.conda/envs/rl_venv/lib/python3.10/site-packages/wandb/sdk/lib/sock_client.py", line 130, in _sendall_with_error_handle
    sent = self._sock.send(data)
BrokenPipeError: [Errno 32] Broken pipe
2025-04-10 16:43:41,870 ERROR   MainThread:3628795 [redirect.py:_on_write():661] [no run ID] error in stderr callback
Traceback (most recent call last):
  File "/home/mila/x/xut/.conda/envs/rl_venv/lib/python3.10/site-packages/wandb/sdk/lib/redirect.py", line 659, in _on_write
    cb(written_data)
  File "/home/mila/x/xut/.conda/envs/rl_venv/lib/python3.10/site-packages/wandb/sdk/wandb_run.py", line 2381, in <lambda>
    lambda data: self._console_raw_callback("stderr", data),
  File "/home/mila/x/xut/.conda/envs/rl_venv/lib/python3.10/site-packages/wandb/sdk/wandb_run.py", line 387, in wrapper
    return func(self, *args, **kwargs)
  File "/home/mila/x/xut/.conda/envs/rl_venv/lib/python3.10/site-packages/wandb/sdk/wandb_run.py", line 435, in wrapper_fn
    return func(self, *args, **kwargs)
  File "/home/mila/x/xut/.conda/envs/rl_venv/lib/python3.10/site-packages/wandb/sdk/wandb_run.py", line 1518, in _console_raw_callback
    self._backend.interface.publish_output_raw(name, data)
  File "/home/mila/x/xut/.conda/envs/rl_venv/lib/python3.10/site-packages/wandb/sdk/interface/interface.py", line 761, in publish_output_raw
    self._publish_output_raw(o)
  File "/home/mila/x/xut/.conda/envs/rl_venv/lib/python3.10/site-packages/wandb/sdk/interface/interface_shared.py", line 38, in _publish_output_raw
    self._publish(rec)
  File "/home/mila/x/xut/.conda/envs/rl_venv/lib/python3.10/site-packages/wandb/sdk/interface/interface_sock.py", line 39, in _publish
    self._sock_client.send_record_publish(record)
  File "/home/mila/x/xut/.conda/envs/rl_venv/lib/python3.10/site-packages/wandb/sdk/lib/sock_client.py", line 174, in send_record_publish
    self.send_server_request(server_req)
  File "/home/mila/x/xut/.conda/envs/rl_venv/lib/python3.10/site-packages/wandb/sdk/lib/sock_client.py", line 154, in send_server_request
    self._send_message(msg)
  File "/home/mila/x/xut/.conda/envs/rl_venv/lib/python3.10/site-packages/wandb/sdk/lib/sock_client.py", line 151, in _send_message
    self._sendall_with_error_handle(header + data)
  File "/home/mila/x/xut/.conda/envs/rl_venv/lib/python3.10/site-packages/wandb/sdk/lib/sock_client.py", line 130, in _sendall_with_error_handle
    sent = self._sock.send(data)
BrokenPipeError: [Errno 32] Broken pipe
2025-04-10 16:43:41,871 ERROR   MainThread:3628795 [redirect.py:_on_write():661] [no run ID] error in stderr callback
Traceback (most recent call last):
  File "/home/mila/x/xut/.conda/envs/rl_venv/lib/python3.10/site-packages/wandb/sdk/lib/redirect.py", line 659, in _on_write
    cb(written_data)
  File "/home/mila/x/xut/.conda/envs/rl_venv/lib/python3.10/site-packages/wandb/sdk/wandb_run.py", line 2381, in <lambda>
    lambda data: self._console_raw_callback("stderr", data),
  File "/home/mila/x/xut/.conda/envs/rl_venv/lib/python3.10/site-packages/wandb/sdk/wandb_run.py", line 387, in wrapper
    return func(self, *args, **kwargs)
  File "/home/mila/x/xut/.conda/envs/rl_venv/lib/python3.10/site-packages/wandb/sdk/wandb_run.py", line 435, in wrapper_fn
    return func(self, *args, **kwargs)
  File "/home/mila/x/xut/.conda/envs/rl_venv/lib/python3.10/site-packages/wandb/sdk/wandb_run.py", line 1518, in _console_raw_callback
    self._backend.interface.publish_output_raw(name, data)
  File "/home/mila/x/xut/.conda/envs/rl_venv/lib/python3.10/site-packages/wandb/sdk/interface/interface.py", line 761, in publish_output_raw
    self._publish_output_raw(o)
  File "/home/mila/x/xut/.conda/envs/rl_venv/lib/python3.10/site-packages/wandb/sdk/interface/interface_shared.py", line 38, in _publish_output_raw
    self._publish(rec)
  File "/home/mila/x/xut/.conda/envs/rl_venv/lib/python3.10/site-packages/wandb/sdk/interface/interface_sock.py", line 39, in _publish
    self._sock_client.send_record_publish(record)
  File "/home/mila/x/xut/.conda/envs/rl_venv/lib/python3.10/site-packages/wandb/sdk/lib/sock_client.py", line 174, in send_record_publish
    self.send_server_request(server_req)
  File "/home/mila/x/xut/.conda/envs/rl_venv/lib/python3.10/site-packages/wandb/sdk/lib/sock_client.py", line 154, in send_server_request
    self._send_message(msg)
  File "/home/mila/x/xut/.conda/envs/rl_venv/lib/python3.10/site-packages/wandb/sdk/lib/sock_client.py", line 151, in _send_message
    self._sendall_with_error_handle(header + data)
  File "/home/mila/x/xut/.conda/envs/rl_venv/lib/python3.10/site-packages/wandb/sdk/lib/sock_client.py", line 130, in _sendall_with_error_handle
    sent = self._sock.send(data)
BrokenPipeError: [Errno 32] Broken pipe
2025-04-10 16:43:41,872 ERROR   MainThread:3628795 [redirect.py:_on_write():661] [no run ID] error in stderr callback
Traceback (most recent call last):
  File "/home/mila/x/xut/.conda/envs/rl_venv/lib/python3.10/site-packages/wandb/sdk/lib/redirect.py", line 659, in _on_write
    cb(written_data)
  File "/home/mila/x/xut/.conda/envs/rl_venv/lib/python3.10/site-packages/wandb/sdk/wandb_run.py", line 2381, in <lambda>
    lambda data: self._console_raw_callback("stderr", data),
  File "/home/mila/x/xut/.conda/envs/rl_venv/lib/python3.10/site-packages/wandb/sdk/wandb_run.py", line 387, in wrapper
    return func(self, *args, **kwargs)
  File "/home/mila/x/xut/.conda/envs/rl_venv/lib/python3.10/site-packages/wandb/sdk/wandb_run.py", line 435, in wrapper_fn
    return func(self, *args, **kwargs)
  File "/home/mila/x/xut/.conda/envs/rl_venv/lib/python3.10/site-packages/wandb/sdk/wandb_run.py", line 1518, in _console_raw_callback
    self._backend.interface.publish_output_raw(name, data)
  File "/home/mila/x/xut/.conda/envs/rl_venv/lib/python3.10/site-packages/wandb/sdk/interface/interface.py", line 761, in publish_output_raw
    self._publish_output_raw(o)
  File "/home/mila/x/xut/.conda/envs/rl_venv/lib/python3.10/site-packages/wandb/sdk/interface/interface_shared.py", line 38, in _publish_output_raw
    self._publish(rec)
  File "/home/mila/x/xut/.conda/envs/rl_venv/lib/python3.10/site-packages/wandb/sdk/interface/interface_sock.py", line 39, in _publish
    self._sock_client.send_record_publish(record)
  File "/home/mila/x/xut/.conda/envs/rl_venv/lib/python3.10/site-packages/wandb/sdk/lib/sock_client.py", line 174, in send_record_publish
    self.send_server_request(server_req)
  File "/home/mila/x/xut/.conda/envs/rl_venv/lib/python3.10/site-packages/wandb/sdk/lib/sock_client.py", line 154, in send_server_request
    self._send_message(msg)
  File "/home/mila/x/xut/.conda/envs/rl_venv/lib/python3.10/site-packages/wandb/sdk/lib/sock_client.py", line 151, in _send_message
    self._sendall_with_error_handle(header + data)
  File "/home/mila/x/xut/.conda/envs/rl_venv/lib/python3.10/site-packages/wandb/sdk/lib/sock_client.py", line 130, in _sendall_with_error_handle
    sent = self._sock.send(data)
BrokenPipeError: [Errno 32] Broken pipe
2025-04-10 16:43:41,873 ERROR   MainThread:3628795 [redirect.py:_on_write():661] [no run ID] error in stderr callback
Traceback (most recent call last):
  File "/home/mila/x/xut/.conda/envs/rl_venv/lib/python3.10/site-packages/wandb/sdk/lib/redirect.py", line 659, in _on_write
    cb(written_data)
  File "/home/mila/x/xut/.conda/envs/rl_venv/lib/python3.10/site-packages/wandb/sdk/wandb_run.py", line 2381, in <lambda>
    lambda data: self._console_raw_callback("stderr", data),
  File "/home/mila/x/xut/.conda/envs/rl_venv/lib/python3.10/site-packages/wandb/sdk/wandb_run.py", line 387, in wrapper
    return func(self, *args, **kwargs)
  File "/home/mila/x/xut/.conda/envs/rl_venv/lib/python3.10/site-packages/wandb/sdk/wandb_run.py", line 435, in wrapper_fn
    return func(self, *args, **kwargs)
  File "/home/mila/x/xut/.conda/envs/rl_venv/lib/python3.10/site-packages/wandb/sdk/wandb_run.py", line 1518, in _console_raw_callback
    self._backend.interface.publish_output_raw(name, data)
  File "/home/mila/x/xut/.conda/envs/rl_venv/lib/python3.10/site-packages/wandb/sdk/interface/interface.py", line 761, in publish_output_raw
    self._publish_output_raw(o)
  File "/home/mila/x/xut/.conda/envs/rl_venv/lib/python3.10/site-packages/wandb/sdk/interface/interface_shared.py", line 38, in _publish_output_raw
    self._publish(rec)
  File "/home/mila/x/xut/.conda/envs/rl_venv/lib/python3.10/site-packages/wandb/sdk/interface/interface_sock.py", line 39, in _publish
    self._sock_client.send_record_publish(record)
  File "/home/mila/x/xut/.conda/envs/rl_venv/lib/python3.10/site-packages/wandb/sdk/lib/sock_client.py", line 174, in send_record_publish
    self.send_server_request(server_req)
  File "/home/mila/x/xut/.conda/envs/rl_venv/lib/python3.10/site-packages/wandb/sdk/lib/sock_client.py", line 154, in send_server_request
    self._send_message(msg)
  File "/home/mila/x/xut/.conda/envs/rl_venv/lib/python3.10/site-packages/wandb/sdk/lib/sock_client.py", line 151, in _send_message
    self._sendall_with_error_handle(header + data)
  File "/home/mila/x/xut/.conda/envs/rl_venv/lib/python3.10/site-packages/wandb/sdk/lib/sock_client.py", line 130, in _sendall_with_error_handle
    sent = self._sock.send(data)
BrokenPipeError: [Errno 32] Broken pipe
2025-04-10 16:43:41,874 ERROR   MainThread:3628795 [redirect.py:_on_write():661] [no run ID] error in stderr callback
Traceback (most recent call last):
  File "/home/mila/x/xut/.conda/envs/rl_venv/lib/python3.10/site-packages/wandb/sdk/lib/redirect.py", line 659, in _on_write
    cb(written_data)
  File "/home/mila/x/xut/.conda/envs/rl_venv/lib/python3.10/site-packages/wandb/sdk/wandb_run.py", line 2381, in <lambda>
    lambda data: self._console_raw_callback("stderr", data),
  File "/home/mila/x/xut/.conda/envs/rl_venv/lib/python3.10/site-packages/wandb/sdk/wandb_run.py", line 387, in wrapper
    return func(self, *args, **kwargs)
  File "/home/mila/x/xut/.conda/envs/rl_venv/lib/python3.10/site-packages/wandb/sdk/wandb_run.py", line 435, in wrapper_fn
    return func(self, *args, **kwargs)
  File "/home/mila/x/xut/.conda/envs/rl_venv/lib/python3.10/site-packages/wandb/sdk/wandb_run.py", line 1518, in _console_raw_callback
    self._backend.interface.publish_output_raw(name, data)
  File "/home/mila/x/xut/.conda/envs/rl_venv/lib/python3.10/site-packages/wandb/sdk/interface/interface.py", line 761, in publish_output_raw
    self._publish_output_raw(o)
  File "/home/mila/x/xut/.conda/envs/rl_venv/lib/python3.10/site-packages/wandb/sdk/interface/interface_shared.py", line 38, in _publish_output_raw
    self._publish(rec)
  File "/home/mila/x/xut/.conda/envs/rl_venv/lib/python3.10/site-packages/wandb/sdk/interface/interface_sock.py", line 39, in _publish
    self._sock_client.send_record_publish(record)
  File "/home/mila/x/xut/.conda/envs/rl_venv/lib/python3.10/site-packages/wandb/sdk/lib/sock_client.py", line 174, in send_record_publish
    self.send_server_request(server_req)
  File "/home/mila/x/xut/.conda/envs/rl_venv/lib/python3.10/site-packages/wandb/sdk/lib/sock_client.py", line 154, in send_server_request
    self._send_message(msg)
  File "/home/mila/x/xut/.conda/envs/rl_venv/lib/python3.10/site-packages/wandb/sdk/lib/sock_client.py", line 151, in _send_message
    self._sendall_with_error_handle(header + data)
  File "/home/mila/x/xut/.conda/envs/rl_venv/lib/python3.10/site-packages/wandb/sdk/lib/sock_client.py", line 130, in _sendall_with_error_handle
    sent = self._sock.send(data)
BrokenPipeError: [Errno 32] Broken pipe
2025-04-10 16:43:41,874 ERROR   MainThread:3628795 [redirect.py:_on_write():661] [no run ID] error in stderr callback
Traceback (most recent call last):
  File "/home/mila/x/xut/.conda/envs/rl_venv/lib/python3.10/site-packages/wandb/sdk/lib/redirect.py", line 659, in _on_write
    cb(written_data)
  File "/home/mila/x/xut/.conda/envs/rl_venv/lib/python3.10/site-packages/wandb/sdk/wandb_run.py", line 2381, in <lambda>
    lambda data: self._console_raw_callback("stderr", data),
  File "/home/mila/x/xut/.conda/envs/rl_venv/lib/python3.10/site-packages/wandb/sdk/wandb_run.py", line 387, in wrapper
    return func(self, *args, **kwargs)
  File "/home/mila/x/xut/.conda/envs/rl_venv/lib/python3.10/site-packages/wandb/sdk/wandb_run.py", line 435, in wrapper_fn
    return func(self, *args, **kwargs)
  File "/home/mila/x/xut/.conda/envs/rl_venv/lib/python3.10/site-packages/wandb/sdk/wandb_run.py", line 1518, in _console_raw_callback
    self._backend.interface.publish_output_raw(name, data)
  File "/home/mila/x/xut/.conda/envs/rl_venv/lib/python3.10/site-packages/wandb/sdk/interface/interface.py", line 761, in publish_output_raw
    self._publish_output_raw(o)
  File "/home/mila/x/xut/.conda/envs/rl_venv/lib/python3.10/site-packages/wandb/sdk/interface/interface_shared.py", line 38, in _publish_output_raw
    self._publish(rec)
  File "/home/mila/x/xut/.conda/envs/rl_venv/lib/python3.10/site-packages/wandb/sdk/interface/interface_sock.py", line 39, in _publish
    self._sock_client.send_record_publish(record)
  File "/home/mila/x/xut/.conda/envs/rl_venv/lib/python3.10/site-packages/wandb/sdk/lib/sock_client.py", line 174, in send_record_publish
    self.send_server_request(server_req)
  File "/home/mila/x/xut/.conda/envs/rl_venv/lib/python3.10/site-packages/wandb/sdk/lib/sock_client.py", line 154, in send_server_request
    self._send_message(msg)
  File "/home/mila/x/xut/.conda/envs/rl_venv/lib/python3.10/site-packages/wandb/sdk/lib/sock_client.py", line 151, in _send_message
    self._sendall_with_error_handle(header + data)
  File "/home/mila/x/xut/.conda/envs/rl_venv/lib/python3.10/site-packages/wandb/sdk/lib/sock_client.py", line 130, in _sendall_with_error_handle
    sent = self._sock.send(data)
BrokenPipeError: [Errno 32] Broken pipe
2025-04-10 16:43:41,876 ERROR   MainThread:3628795 [redirect.py:_on_write():661] [no run ID] error in stderr callback
Traceback (most recent call last):
  File "/home/mila/x/xut/.conda/envs/rl_venv/lib/python3.10/site-packages/wandb/sdk/lib/redirect.py", line 659, in _on_write
    cb(written_data)
  File "/home/mila/x/xut/.conda/envs/rl_venv/lib/python3.10/site-packages/wandb/sdk/wandb_run.py", line 2381, in <lambda>
    lambda data: self._console_raw_callback("stderr", data),
  File "/home/mila/x/xut/.conda/envs/rl_venv/lib/python3.10/site-packages/wandb/sdk/wandb_run.py", line 387, in wrapper
    return func(self, *args, **kwargs)
  File "/home/mila/x/xut/.conda/envs/rl_venv/lib/python3.10/site-packages/wandb/sdk/wandb_run.py", line 435, in wrapper_fn
    return func(self, *args, **kwargs)
  File "/home/mila/x/xut/.conda/envs/rl_venv/lib/python3.10/site-packages/wandb/sdk/wandb_run.py", line 1518, in _console_raw_callback
    self._backend.interface.publish_output_raw(name, data)
  File "/home/mila/x/xut/.conda/envs/rl_venv/lib/python3.10/site-packages/wandb/sdk/interface/interface.py", line 761, in publish_output_raw
    self._publish_output_raw(o)
  File "/home/mila/x/xut/.conda/envs/rl_venv/lib/python3.10/site-packages/wandb/sdk/interface/interface_shared.py", line 38, in _publish_output_raw
    self._publish(rec)
  File "/home/mila/x/xut/.conda/envs/rl_venv/lib/python3.10/site-packages/wandb/sdk/interface/interface_sock.py", line 39, in _publish
    self._sock_client.send_record_publish(record)
  File "/home/mila/x/xut/.conda/envs/rl_venv/lib/python3.10/site-packages/wandb/sdk/lib/sock_client.py", line 174, in send_record_publish
    self.send_server_request(server_req)
  File "/home/mila/x/xut/.conda/envs/rl_venv/lib/python3.10/site-packages/wandb/sdk/lib/sock_client.py", line 154, in send_server_request
    self._send_message(msg)
  File "/home/mila/x/xut/.conda/envs/rl_venv/lib/python3.10/site-packages/wandb/sdk/lib/sock_client.py", line 151, in _send_message
    self._sendall_with_error_handle(header + data)
  File "/home/mila/x/xut/.conda/envs/rl_venv/lib/python3.10/site-packages/wandb/sdk/lib/sock_client.py", line 130, in _sendall_with_error_handle
    sent = self._sock.send(data)
BrokenPipeError: [Errno 32] Broken pipe
2025-04-10 16:43:41,876 ERROR   MainThread:3628795 [redirect.py:_on_write():661] [no run ID] error in stderr callback
Traceback (most recent call last):
  File "/home/mila/x/xut/.conda/envs/rl_venv/lib/python3.10/site-packages/wandb/sdk/lib/redirect.py", line 659, in _on_write
    cb(written_data)
  File "/home/mila/x/xut/.conda/envs/rl_venv/lib/python3.10/site-packages/wandb/sdk/wandb_run.py", line 2381, in <lambda>
    lambda data: self._console_raw_callback("stderr", data),
  File "/home/mila/x/xut/.conda/envs/rl_venv/lib/python3.10/site-packages/wandb/sdk/wandb_run.py", line 387, in wrapper
    return func(self, *args, **kwargs)
  File "/home/mila/x/xut/.conda/envs/rl_venv/lib/python3.10/site-packages/wandb/sdk/wandb_run.py", line 435, in wrapper_fn
    return func(self, *args, **kwargs)
  File "/home/mila/x/xut/.conda/envs/rl_venv/lib/python3.10/site-packages/wandb/sdk/wandb_run.py", line 1518, in _console_raw_callback
    self._backend.interface.publish_output_raw(name, data)
  File "/home/mila/x/xut/.conda/envs/rl_venv/lib/python3.10/site-packages/wandb/sdk/interface/interface.py", line 761, in publish_output_raw
    self._publish_output_raw(o)
  File "/home/mila/x/xut/.conda/envs/rl_venv/lib/python3.10/site-packages/wandb/sdk/interface/interface_shared.py", line 38, in _publish_output_raw
    self._publish(rec)
  File "/home/mila/x/xut/.conda/envs/rl_venv/lib/python3.10/site-packages/wandb/sdk/interface/interface_sock.py", line 39, in _publish
    self._sock_client.send_record_publish(record)
  File "/home/mila/x/xut/.conda/envs/rl_venv/lib/python3.10/site-packages/wandb/sdk/lib/sock_client.py", line 174, in send_record_publish
    self.send_server_request(server_req)
  File "/home/mila/x/xut/.conda/envs/rl_venv/lib/python3.10/site-packages/wandb/sdk/lib/sock_client.py", line 154, in send_server_request
    self._send_message(msg)
  File "/home/mila/x/xut/.conda/envs/rl_venv/lib/python3.10/site-packages/wandb/sdk/lib/sock_client.py", line 151, in _send_message
    self._sendall_with_error_handle(header + data)
  File "/home/mila/x/xut/.conda/envs/rl_venv/lib/python3.10/site-packages/wandb/sdk/lib/sock_client.py", line 130, in _sendall_with_error_handle
    sent = self._sock.send(data)
BrokenPipeError: [Errno 32] Broken pipe
2025-04-10 16:43:41,877 ERROR   MainThread:3628795 [redirect.py:_on_write():661] [no run ID] error in stderr callback
Traceback (most recent call last):
  File "/home/mila/x/xut/.conda/envs/rl_venv/lib/python3.10/site-packages/wandb/sdk/lib/redirect.py", line 659, in _on_write
    cb(written_data)
  File "/home/mila/x/xut/.conda/envs/rl_venv/lib/python3.10/site-packages/wandb/sdk/wandb_run.py", line 2381, in <lambda>
    lambda data: self._console_raw_callback("stderr", data),
  File "/home/mila/x/xut/.conda/envs/rl_venv/lib/python3.10/site-packages/wandb/sdk/wandb_run.py", line 387, in wrapper
    return func(self, *args, **kwargs)
  File "/home/mila/x/xut/.conda/envs/rl_venv/lib/python3.10/site-packages/wandb/sdk/wandb_run.py", line 435, in wrapper_fn
    return func(self, *args, **kwargs)
  File "/home/mila/x/xut/.conda/envs/rl_venv/lib/python3.10/site-packages/wandb/sdk/wandb_run.py", line 1518, in _console_raw_callback
    self._backend.interface.publish_output_raw(name, data)
  File "/home/mila/x/xut/.conda/envs/rl_venv/lib/python3.10/site-packages/wandb/sdk/interface/interface.py", line 761, in publish_output_raw
    self._publish_output_raw(o)
  File "/home/mila/x/xut/.conda/envs/rl_venv/lib/python3.10/site-packages/wandb/sdk/interface/interface_shared.py", line 38, in _publish_output_raw
    self._publish(rec)
  File "/home/mila/x/xut/.conda/envs/rl_venv/lib/python3.10/site-packages/wandb/sdk/interface/interface_sock.py", line 39, in _publish
    self._sock_client.send_record_publish(record)
  File "/home/mila/x/xut/.conda/envs/rl_venv/lib/python3.10/site-packages/wandb/sdk/lib/sock_client.py", line 174, in send_record_publish
    self.send_server_request(server_req)
  File "/home/mila/x/xut/.conda/envs/rl_venv/lib/python3.10/site-packages/wandb/sdk/lib/sock_client.py", line 154, in send_server_request
    self._send_message(msg)
  File "/home/mila/x/xut/.conda/envs/rl_venv/lib/python3.10/site-packages/wandb/sdk/lib/sock_client.py", line 151, in _send_message
    self._sendall_with_error_handle(header + data)
  File "/home/mila/x/xut/.conda/envs/rl_venv/lib/python3.10/site-packages/wandb/sdk/lib/sock_client.py", line 130, in _sendall_with_error_handle
    sent = self._sock.send(data)
BrokenPipeError: [Errno 32] Broken pipe
2025-04-10 16:43:41,877 ERROR   MainThread:3628795 [redirect.py:_on_write():661] [no run ID] error in stderr callback
Traceback (most recent call last):
  File "/home/mila/x/xut/.conda/envs/rl_venv/lib/python3.10/site-packages/wandb/sdk/lib/redirect.py", line 659, in _on_write
    cb(written_data)
  File "/home/mila/x/xut/.conda/envs/rl_venv/lib/python3.10/site-packages/wandb/sdk/wandb_run.py", line 2381, in <lambda>
    lambda data: self._console_raw_callback("stderr", data),
  File "/home/mila/x/xut/.conda/envs/rl_venv/lib/python3.10/site-packages/wandb/sdk/wandb_run.py", line 387, in wrapper
    return func(self, *args, **kwargs)
  File "/home/mila/x/xut/.conda/envs/rl_venv/lib/python3.10/site-packages/wandb/sdk/wandb_run.py", line 435, in wrapper_fn
    return func(self, *args, **kwargs)
  File "/home/mila/x/xut/.conda/envs/rl_venv/lib/python3.10/site-packages/wandb/sdk/wandb_run.py", line 1518, in _console_raw_callback
    self._backend.interface.publish_output_raw(name, data)
  File "/home/mila/x/xut/.conda/envs/rl_venv/lib/python3.10/site-packages/wandb/sdk/interface/interface.py", line 761, in publish_output_raw
    self._publish_output_raw(o)
  File "/home/mila/x/xut/.conda/envs/rl_venv/lib/python3.10/site-packages/wandb/sdk/interface/interface_shared.py", line 38, in _publish_output_raw
    self._publish(rec)
  File "/home/mila/x/xut/.conda/envs/rl_venv/lib/python3.10/site-packages/wandb/sdk/interface/interface_sock.py", line 39, in _publish
    self._sock_client.send_record_publish(record)
  File "/home/mila/x/xut/.conda/envs/rl_venv/lib/python3.10/site-packages/wandb/sdk/lib/sock_client.py", line 174, in send_record_publish
    self.send_server_request(server_req)
  File "/home/mila/x/xut/.conda/envs/rl_venv/lib/python3.10/site-packages/wandb/sdk/lib/sock_client.py", line 154, in send_server_request
    self._send_message(msg)
  File "/home/mila/x/xut/.conda/envs/rl_venv/lib/python3.10/site-packages/wandb/sdk/lib/sock_client.py", line 151, in _send_message
    self._sendall_with_error_handle(header + data)
  File "/home/mila/x/xut/.conda/envs/rl_venv/lib/python3.10/site-packages/wandb/sdk/lib/sock_client.py", line 130, in _sendall_with_error_handle
    sent = self._sock.send(data)
BrokenPipeError: [Errno 32] Broken pipe
2025-04-10 16:43:41,881 ERROR   MainThread:3628795 [redirect.py:_on_write():661] [no run ID] error in stderr callback
Traceback (most recent call last):
  File "/home/mila/x/xut/.conda/envs/rl_venv/lib/python3.10/site-packages/wandb/sdk/lib/redirect.py", line 659, in _on_write
    cb(written_data)
  File "/home/mila/x/xut/.conda/envs/rl_venv/lib/python3.10/site-packages/wandb/sdk/wandb_run.py", line 2381, in <lambda>
    lambda data: self._console_raw_callback("stderr", data),
  File "/home/mila/x/xut/.conda/envs/rl_venv/lib/python3.10/site-packages/wandb/sdk/wandb_run.py", line 387, in wrapper
    return func(self, *args, **kwargs)
  File "/home/mila/x/xut/.conda/envs/rl_venv/lib/python3.10/site-packages/wandb/sdk/wandb_run.py", line 435, in wrapper_fn
    return func(self, *args, **kwargs)
  File "/home/mila/x/xut/.conda/envs/rl_venv/lib/python3.10/site-packages/wandb/sdk/wandb_run.py", line 1518, in _console_raw_callback
    self._backend.interface.publish_output_raw(name, data)
  File "/home/mila/x/xut/.conda/envs/rl_venv/lib/python3.10/site-packages/wandb/sdk/interface/interface.py", line 761, in publish_output_raw
    self._publish_output_raw(o)
  File "/home/mila/x/xut/.conda/envs/rl_venv/lib/python3.10/site-packages/wandb/sdk/interface/interface_shared.py", line 38, in _publish_output_raw
    self._publish(rec)
  File "/home/mila/x/xut/.conda/envs/rl_venv/lib/python3.10/site-packages/wandb/sdk/interface/interface_sock.py", line 39, in _publish
    self._sock_client.send_record_publish(record)
  File "/home/mila/x/xut/.conda/envs/rl_venv/lib/python3.10/site-packages/wandb/sdk/lib/sock_client.py", line 174, in send_record_publish
    self.send_server_request(server_req)
  File "/home/mila/x/xut/.conda/envs/rl_venv/lib/python3.10/site-packages/wandb/sdk/lib/sock_client.py", line 154, in send_server_request
    self._send_message(msg)
  File "/home/mila/x/xut/.conda/envs/rl_venv/lib/python3.10/site-packages/wandb/sdk/lib/sock_client.py", line 151, in _send_message
    self._sendall_with_error_handle(header + data)
  File "/home/mila/x/xut/.conda/envs/rl_venv/lib/python3.10/site-packages/wandb/sdk/lib/sock_client.py", line 130, in _sendall_with_error_handle
    sent = self._sock.send(data)
BrokenPipeError: [Errno 32] Broken pipe
2025-04-10 16:43:41,881 ERROR   MainThread:3628795 [redirect.py:_on_write():661] [no run ID] error in stderr callback
Traceback (most recent call last):
  File "/home/mila/x/xut/.conda/envs/rl_venv/lib/python3.10/site-packages/wandb/sdk/lib/redirect.py", line 659, in _on_write
    cb(written_data)
  File "/home/mila/x/xut/.conda/envs/rl_venv/lib/python3.10/site-packages/wandb/sdk/wandb_run.py", line 2381, in <lambda>
    lambda data: self._console_raw_callback("stderr", data),
  File "/home/mila/x/xut/.conda/envs/rl_venv/lib/python3.10/site-packages/wandb/sdk/wandb_run.py", line 387, in wrapper
    return func(self, *args, **kwargs)
  File "/home/mila/x/xut/.conda/envs/rl_venv/lib/python3.10/site-packages/wandb/sdk/wandb_run.py", line 435, in wrapper_fn
    return func(self, *args, **kwargs)
  File "/home/mila/x/xut/.conda/envs/rl_venv/lib/python3.10/site-packages/wandb/sdk/wandb_run.py", line 1518, in _console_raw_callback
    self._backend.interface.publish_output_raw(name, data)
  File "/home/mila/x/xut/.conda/envs/rl_venv/lib/python3.10/site-packages/wandb/sdk/interface/interface.py", line 761, in publish_output_raw
    self._publish_output_raw(o)
  File "/home/mila/x/xut/.conda/envs/rl_venv/lib/python3.10/site-packages/wandb/sdk/interface/interface_shared.py", line 38, in _publish_output_raw
    self._publish(rec)
  File "/home/mila/x/xut/.conda/envs/rl_venv/lib/python3.10/site-packages/wandb/sdk/interface/interface_sock.py", line 39, in _publish
    self._sock_client.send_record_publish(record)
  File "/home/mila/x/xut/.conda/envs/rl_venv/lib/python3.10/site-packages/wandb/sdk/lib/sock_client.py", line 174, in send_record_publish
    self.send_server_request(server_req)
  File "/home/mila/x/xut/.conda/envs/rl_venv/lib/python3.10/site-packages/wandb/sdk/lib/sock_client.py", line 154, in send_server_request
    self._send_message(msg)
  File "/home/mila/x/xut/.conda/envs/rl_venv/lib/python3.10/site-packages/wandb/sdk/lib/sock_client.py", line 151, in _send_message
    self._sendall_with_error_handle(header + data)
  File "/home/mila/x/xut/.conda/envs/rl_venv/lib/python3.10/site-packages/wandb/sdk/lib/sock_client.py", line 130, in _sendall_with_error_handle
    sent = self._sock.send(data)
BrokenPipeError: [Errno 32] Broken pipe
2025-04-10 16:43:41,882 ERROR   MainThread:3628795 [redirect.py:_on_write():661] [no run ID] error in stderr callback
Traceback (most recent call last):
  File "/home/mila/x/xut/.conda/envs/rl_venv/lib/python3.10/site-packages/wandb/sdk/lib/redirect.py", line 659, in _on_write
    cb(written_data)
  File "/home/mila/x/xut/.conda/envs/rl_venv/lib/python3.10/site-packages/wandb/sdk/wandb_run.py", line 2381, in <lambda>
    lambda data: self._console_raw_callback("stderr", data),
  File "/home/mila/x/xut/.conda/envs/rl_venv/lib/python3.10/site-packages/wandb/sdk/wandb_run.py", line 387, in wrapper
    return func(self, *args, **kwargs)
  File "/home/mila/x/xut/.conda/envs/rl_venv/lib/python3.10/site-packages/wandb/sdk/wandb_run.py", line 435, in wrapper_fn
    return func(self, *args, **kwargs)
  File "/home/mila/x/xut/.conda/envs/rl_venv/lib/python3.10/site-packages/wandb/sdk/wandb_run.py", line 1518, in _console_raw_callback
    self._backend.interface.publish_output_raw(name, data)
  File "/home/mila/x/xut/.conda/envs/rl_venv/lib/python3.10/site-packages/wandb/sdk/interface/interface.py", line 761, in publish_output_raw
    self._publish_output_raw(o)
  File "/home/mila/x/xut/.conda/envs/rl_venv/lib/python3.10/site-packages/wandb/sdk/interface/interface_shared.py", line 38, in _publish_output_raw
    self._publish(rec)
  File "/home/mila/x/xut/.conda/envs/rl_venv/lib/python3.10/site-packages/wandb/sdk/interface/interface_sock.py", line 39, in _publish
    self._sock_client.send_record_publish(record)
  File "/home/mila/x/xut/.conda/envs/rl_venv/lib/python3.10/site-packages/wandb/sdk/lib/sock_client.py", line 174, in send_record_publish
    self.send_server_request(server_req)
  File "/home/mila/x/xut/.conda/envs/rl_venv/lib/python3.10/site-packages/wandb/sdk/lib/sock_client.py", line 154, in send_server_request
    self._send_message(msg)
  File "/home/mila/x/xut/.conda/envs/rl_venv/lib/python3.10/site-packages/wandb/sdk/lib/sock_client.py", line 151, in _send_message
    self._sendall_with_error_handle(header + data)
  File "/home/mila/x/xut/.conda/envs/rl_venv/lib/python3.10/site-packages/wandb/sdk/lib/sock_client.py", line 130, in _sendall_with_error_handle
    sent = self._sock.send(data)
BrokenPipeError: [Errno 32] Broken pipe
2025-04-10 16:43:41,882 ERROR   MainThread:3628795 [redirect.py:_on_write():661] [no run ID] error in stderr callback
Traceback (most recent call last):
  File "/home/mila/x/xut/.conda/envs/rl_venv/lib/python3.10/site-packages/wandb/sdk/lib/redirect.py", line 659, in _on_write
    cb(written_data)
  File "/home/mila/x/xut/.conda/envs/rl_venv/lib/python3.10/site-packages/wandb/sdk/wandb_run.py", line 2381, in <lambda>
    lambda data: self._console_raw_callback("stderr", data),
  File "/home/mila/x/xut/.conda/envs/rl_venv/lib/python3.10/site-packages/wandb/sdk/wandb_run.py", line 387, in wrapper
    return func(self, *args, **kwargs)
  File "/home/mila/x/xut/.conda/envs/rl_venv/lib/python3.10/site-packages/wandb/sdk/wandb_run.py", line 435, in wrapper_fn
    return func(self, *args, **kwargs)
  File "/home/mila/x/xut/.conda/envs/rl_venv/lib/python3.10/site-packages/wandb/sdk/wandb_run.py", line 1518, in _console_raw_callback
    self._backend.interface.publish_output_raw(name, data)
  File "/home/mila/x/xut/.conda/envs/rl_venv/lib/python3.10/site-packages/wandb/sdk/interface/interface.py", line 761, in publish_output_raw
    self._publish_output_raw(o)
  File "/home/mila/x/xut/.conda/envs/rl_venv/lib/python3.10/site-packages/wandb/sdk/interface/interface_shared.py", line 38, in _publish_output_raw
    self._publish(rec)
  File "/home/mila/x/xut/.conda/envs/rl_venv/lib/python3.10/site-packages/wandb/sdk/interface/interface_sock.py", line 39, in _publish
    self._sock_client.send_record_publish(record)
  File "/home/mila/x/xut/.conda/envs/rl_venv/lib/python3.10/site-packages/wandb/sdk/lib/sock_client.py", line 174, in send_record_publish
    self.send_server_request(server_req)
  File "/home/mila/x/xut/.conda/envs/rl_venv/lib/python3.10/site-packages/wandb/sdk/lib/sock_client.py", line 154, in send_server_request
    self._send_message(msg)
  File "/home/mila/x/xut/.conda/envs/rl_venv/lib/python3.10/site-packages/wandb/sdk/lib/sock_client.py", line 151, in _send_message
    self._sendall_with_error_handle(header + data)
  File "/home/mila/x/xut/.conda/envs/rl_venv/lib/python3.10/site-packages/wandb/sdk/lib/sock_client.py", line 130, in _sendall_with_error_handle
    sent = self._sock.send(data)
BrokenPipeError: [Errno 32] Broken pipe
2025-04-10 16:43:41,884 ERROR   MainThread:3628795 [redirect.py:_on_write():661] [no run ID] error in stderr callback
Traceback (most recent call last):
  File "/home/mila/x/xut/.conda/envs/rl_venv/lib/python3.10/site-packages/wandb/sdk/lib/redirect.py", line 659, in _on_write
    cb(written_data)
  File "/home/mila/x/xut/.conda/envs/rl_venv/lib/python3.10/site-packages/wandb/sdk/wandb_run.py", line 2381, in <lambda>
    lambda data: self._console_raw_callback("stderr", data),
  File "/home/mila/x/xut/.conda/envs/rl_venv/lib/python3.10/site-packages/wandb/sdk/wandb_run.py", line 387, in wrapper
    return func(self, *args, **kwargs)
  File "/home/mila/x/xut/.conda/envs/rl_venv/lib/python3.10/site-packages/wandb/sdk/wandb_run.py", line 435, in wrapper_fn
    return func(self, *args, **kwargs)
  File "/home/mila/x/xut/.conda/envs/rl_venv/lib/python3.10/site-packages/wandb/sdk/wandb_run.py", line 1518, in _console_raw_callback
    self._backend.interface.publish_output_raw(name, data)
  File "/home/mila/x/xut/.conda/envs/rl_venv/lib/python3.10/site-packages/wandb/sdk/interface/interface.py", line 761, in publish_output_raw
    self._publish_output_raw(o)
  File "/home/mila/x/xut/.conda/envs/rl_venv/lib/python3.10/site-packages/wandb/sdk/interface/interface_shared.py", line 38, in _publish_output_raw
    self._publish(rec)
  File "/home/mila/x/xut/.conda/envs/rl_venv/lib/python3.10/site-packages/wandb/sdk/interface/interface_sock.py", line 39, in _publish
    self._sock_client.send_record_publish(record)
  File "/home/mila/x/xut/.conda/envs/rl_venv/lib/python3.10/site-packages/wandb/sdk/lib/sock_client.py", line 174, in send_record_publish
    self.send_server_request(server_req)
  File "/home/mila/x/xut/.conda/envs/rl_venv/lib/python3.10/site-packages/wandb/sdk/lib/sock_client.py", line 154, in send_server_request
    self._send_message(msg)
  File "/home/mila/x/xut/.conda/envs/rl_venv/lib/python3.10/site-packages/wandb/sdk/lib/sock_client.py", line 151, in _send_message
    self._sendall_with_error_handle(header + data)
  File "/home/mila/x/xut/.conda/envs/rl_venv/lib/python3.10/site-packages/wandb/sdk/lib/sock_client.py", line 130, in _sendall_with_error_handle
    sent = self._sock.send(data)
BrokenPipeError: [Errno 32] Broken pipe
2025-04-10 16:43:41,885 ERROR   MainThread:3628795 [redirect.py:_on_write():661] [no run ID] error in stderr callback
Traceback (most recent call last):
  File "/home/mila/x/xut/.conda/envs/rl_venv/lib/python3.10/site-packages/wandb/sdk/lib/redirect.py", line 659, in _on_write
    cb(written_data)
  File "/home/mila/x/xut/.conda/envs/rl_venv/lib/python3.10/site-packages/wandb/sdk/wandb_run.py", line 2381, in <lambda>
    lambda data: self._console_raw_callback("stderr", data),
  File "/home/mila/x/xut/.conda/envs/rl_venv/lib/python3.10/site-packages/wandb/sdk/wandb_run.py", line 387, in wrapper
    return func(self, *args, **kwargs)
  File "/home/mila/x/xut/.conda/envs/rl_venv/lib/python3.10/site-packages/wandb/sdk/wandb_run.py", line 435, in wrapper_fn
    return func(self, *args, **kwargs)
  File "/home/mila/x/xut/.conda/envs/rl_venv/lib/python3.10/site-packages/wandb/sdk/wandb_run.py", line 1518, in _console_raw_callback
    self._backend.interface.publish_output_raw(name, data)
  File "/home/mila/x/xut/.conda/envs/rl_venv/lib/python3.10/site-packages/wandb/sdk/interface/interface.py", line 761, in publish_output_raw
    self._publish_output_raw(o)
  File "/home/mila/x/xut/.conda/envs/rl_venv/lib/python3.10/site-packages/wandb/sdk/interface/interface_shared.py", line 38, in _publish_output_raw
    self._publish(rec)
  File "/home/mila/x/xut/.conda/envs/rl_venv/lib/python3.10/site-packages/wandb/sdk/interface/interface_sock.py", line 39, in _publish
    self._sock_client.send_record_publish(record)
  File "/home/mila/x/xut/.conda/envs/rl_venv/lib/python3.10/site-packages/wandb/sdk/lib/sock_client.py", line 174, in send_record_publish
    self.send_server_request(server_req)
  File "/home/mila/x/xut/.conda/envs/rl_venv/lib/python3.10/site-packages/wandb/sdk/lib/sock_client.py", line 154, in send_server_request
    self._send_message(msg)
  File "/home/mila/x/xut/.conda/envs/rl_venv/lib/python3.10/site-packages/wandb/sdk/lib/sock_client.py", line 151, in _send_message
    self._sendall_with_error_handle(header + data)
  File "/home/mila/x/xut/.conda/envs/rl_venv/lib/python3.10/site-packages/wandb/sdk/lib/sock_client.py", line 130, in _sendall_with_error_handle
    sent = self._sock.send(data)
BrokenPipeError: [Errno 32] Broken pipe
2025-04-10 16:43:41,885 ERROR   MainThread:3628795 [redirect.py:_on_write():661] [no run ID] error in stderr callback
Traceback (most recent call last):
  File "/home/mila/x/xut/.conda/envs/rl_venv/lib/python3.10/site-packages/wandb/sdk/lib/redirect.py", line 659, in _on_write
    cb(written_data)
  File "/home/mila/x/xut/.conda/envs/rl_venv/lib/python3.10/site-packages/wandb/sdk/wandb_run.py", line 2381, in <lambda>
    lambda data: self._console_raw_callback("stderr", data),
  File "/home/mila/x/xut/.conda/envs/rl_venv/lib/python3.10/site-packages/wandb/sdk/wandb_run.py", line 387, in wrapper
    return func(self, *args, **kwargs)
  File "/home/mila/x/xut/.conda/envs/rl_venv/lib/python3.10/site-packages/wandb/sdk/wandb_run.py", line 435, in wrapper_fn
    return func(self, *args, **kwargs)
  File "/home/mila/x/xut/.conda/envs/rl_venv/lib/python3.10/site-packages/wandb/sdk/wandb_run.py", line 1518, in _console_raw_callback
    self._backend.interface.publish_output_raw(name, data)
  File "/home/mila/x/xut/.conda/envs/rl_venv/lib/python3.10/site-packages/wandb/sdk/interface/interface.py", line 761, in publish_output_raw
    self._publish_output_raw(o)
  File "/home/mila/x/xut/.conda/envs/rl_venv/lib/python3.10/site-packages/wandb/sdk/interface/interface_shared.py", line 38, in _publish_output_raw
    self._publish(rec)
  File "/home/mila/x/xut/.conda/envs/rl_venv/lib/python3.10/site-packages/wandb/sdk/interface/interface_sock.py", line 39, in _publish
    self._sock_client.send_record_publish(record)
  File "/home/mila/x/xut/.conda/envs/rl_venv/lib/python3.10/site-packages/wandb/sdk/lib/sock_client.py", line 174, in send_record_publish
    self.send_server_request(server_req)
  File "/home/mila/x/xut/.conda/envs/rl_venv/lib/python3.10/site-packages/wandb/sdk/lib/sock_client.py", line 154, in send_server_request
    self._send_message(msg)
  File "/home/mila/x/xut/.conda/envs/rl_venv/lib/python3.10/site-packages/wandb/sdk/lib/sock_client.py", line 151, in _send_message
    self._sendall_with_error_handle(header + data)
  File "/home/mila/x/xut/.conda/envs/rl_venv/lib/python3.10/site-packages/wandb/sdk/lib/sock_client.py", line 130, in _sendall_with_error_handle
    sent = self._sock.send(data)
BrokenPipeError: [Errno 32] Broken pipe
2025-04-10 16:43:41,886 ERROR   MainThread:3628795 [redirect.py:_on_write():661] [no run ID] error in stderr callback
Traceback (most recent call last):
  File "/home/mila/x/xut/.conda/envs/rl_venv/lib/python3.10/site-packages/wandb/sdk/lib/redirect.py", line 659, in _on_write
    cb(written_data)
  File "/home/mila/x/xut/.conda/envs/rl_venv/lib/python3.10/site-packages/wandb/sdk/wandb_run.py", line 2381, in <lambda>
    lambda data: self._console_raw_callback("stderr", data),
  File "/home/mila/x/xut/.conda/envs/rl_venv/lib/python3.10/site-packages/wandb/sdk/wandb_run.py", line 387, in wrapper
    return func(self, *args, **kwargs)
  File "/home/mila/x/xut/.conda/envs/rl_venv/lib/python3.10/site-packages/wandb/sdk/wandb_run.py", line 435, in wrapper_fn
    return func(self, *args, **kwargs)
  File "/home/mila/x/xut/.conda/envs/rl_venv/lib/python3.10/site-packages/wandb/sdk/wandb_run.py", line 1518, in _console_raw_callback
    self._backend.interface.publish_output_raw(name, data)
  File "/home/mila/x/xut/.conda/envs/rl_venv/lib/python3.10/site-packages/wandb/sdk/interface/interface.py", line 761, in publish_output_raw
    self._publish_output_raw(o)
  File "/home/mila/x/xut/.conda/envs/rl_venv/lib/python3.10/site-packages/wandb/sdk/interface/interface_shared.py", line 38, in _publish_output_raw
    self._publish(rec)
  File "/home/mila/x/xut/.conda/envs/rl_venv/lib/python3.10/site-packages/wandb/sdk/interface/interface_sock.py", line 39, in _publish
    self._sock_client.send_record_publish(record)
  File "/home/mila/x/xut/.conda/envs/rl_venv/lib/python3.10/site-packages/wandb/sdk/lib/sock_client.py", line 174, in send_record_publish
    self.send_server_request(server_req)
  File "/home/mila/x/xut/.conda/envs/rl_venv/lib/python3.10/site-packages/wandb/sdk/lib/sock_client.py", line 154, in send_server_request
    self._send_message(msg)
  File "/home/mila/x/xut/.conda/envs/rl_venv/lib/python3.10/site-packages/wandb/sdk/lib/sock_client.py", line 151, in _send_message
    self._sendall_with_error_handle(header + data)
  File "/home/mila/x/xut/.conda/envs/rl_venv/lib/python3.10/site-packages/wandb/sdk/lib/sock_client.py", line 130, in _sendall_with_error_handle
    sent = self._sock.send(data)
BrokenPipeError: [Errno 32] Broken pipe
2025-04-10 16:43:41,888 ERROR   MainThread:3628795 [redirect.py:_on_write():661] [no run ID] error in stderr callback
Traceback (most recent call last):
  File "/home/mila/x/xut/.conda/envs/rl_venv/lib/python3.10/site-packages/wandb/sdk/lib/redirect.py", line 659, in _on_write
    cb(written_data)
  File "/home/mila/x/xut/.conda/envs/rl_venv/lib/python3.10/site-packages/wandb/sdk/wandb_run.py", line 2381, in <lambda>
    lambda data: self._console_raw_callback("stderr", data),
  File "/home/mila/x/xut/.conda/envs/rl_venv/lib/python3.10/site-packages/wandb/sdk/wandb_run.py", line 387, in wrapper
    return func(self, *args, **kwargs)
  File "/home/mila/x/xut/.conda/envs/rl_venv/lib/python3.10/site-packages/wandb/sdk/wandb_run.py", line 435, in wrapper_fn
    return func(self, *args, **kwargs)
  File "/home/mila/x/xut/.conda/envs/rl_venv/lib/python3.10/site-packages/wandb/sdk/wandb_run.py", line 1518, in _console_raw_callback
    self._backend.interface.publish_output_raw(name, data)
  File "/home/mila/x/xut/.conda/envs/rl_venv/lib/python3.10/site-packages/wandb/sdk/interface/interface.py", line 761, in publish_output_raw
    self._publish_output_raw(o)
  File "/home/mila/x/xut/.conda/envs/rl_venv/lib/python3.10/site-packages/wandb/sdk/interface/interface_shared.py", line 38, in _publish_output_raw
    self._publish(rec)
  File "/home/mila/x/xut/.conda/envs/rl_venv/lib/python3.10/site-packages/wandb/sdk/interface/interface_sock.py", line 39, in _publish
    self._sock_client.send_record_publish(record)
  File "/home/mila/x/xut/.conda/envs/rl_venv/lib/python3.10/site-packages/wandb/sdk/lib/sock_client.py", line 174, in send_record_publish
    self.send_server_request(server_req)
  File "/home/mila/x/xut/.conda/envs/rl_venv/lib/python3.10/site-packages/wandb/sdk/lib/sock_client.py", line 154, in send_server_request
    self._send_message(msg)
  File "/home/mila/x/xut/.conda/envs/rl_venv/lib/python3.10/site-packages/wandb/sdk/lib/sock_client.py", line 151, in _send_message
    self._sendall_with_error_handle(header + data)
  File "/home/mila/x/xut/.conda/envs/rl_venv/lib/python3.10/site-packages/wandb/sdk/lib/sock_client.py", line 130, in _sendall_with_error_handle
    sent = self._sock.send(data)
BrokenPipeError: [Errno 32] Broken pipe
2025-04-10 16:43:41,888 ERROR   MainThread:3628795 [redirect.py:_on_write():661] [no run ID] error in stderr callback
Traceback (most recent call last):
  File "/home/mila/x/xut/.conda/envs/rl_venv/lib/python3.10/site-packages/wandb/sdk/lib/redirect.py", line 659, in _on_write
    cb(written_data)
  File "/home/mila/x/xut/.conda/envs/rl_venv/lib/python3.10/site-packages/wandb/sdk/wandb_run.py", line 2381, in <lambda>
    lambda data: self._console_raw_callback("stderr", data),
  File "/home/mila/x/xut/.conda/envs/rl_venv/lib/python3.10/site-packages/wandb/sdk/wandb_run.py", line 387, in wrapper
    return func(self, *args, **kwargs)
  File "/home/mila/x/xut/.conda/envs/rl_venv/lib/python3.10/site-packages/wandb/sdk/wandb_run.py", line 435, in wrapper_fn
    return func(self, *args, **kwargs)
  File "/home/mila/x/xut/.conda/envs/rl_venv/lib/python3.10/site-packages/wandb/sdk/wandb_run.py", line 1518, in _console_raw_callback
    self._backend.interface.publish_output_raw(name, data)
  File "/home/mila/x/xut/.conda/envs/rl_venv/lib/python3.10/site-packages/wandb/sdk/interface/interface.py", line 761, in publish_output_raw
    self._publish_output_raw(o)
  File "/home/mila/x/xut/.conda/envs/rl_venv/lib/python3.10/site-packages/wandb/sdk/interface/interface_shared.py", line 38, in _publish_output_raw
    self._publish(rec)
  File "/home/mila/x/xut/.conda/envs/rl_venv/lib/python3.10/site-packages/wandb/sdk/interface/interface_sock.py", line 39, in _publish
    self._sock_client.send_record_publish(record)
  File "/home/mila/x/xut/.conda/envs/rl_venv/lib/python3.10/site-packages/wandb/sdk/lib/sock_client.py", line 174, in send_record_publish
    self.send_server_request(server_req)
  File "/home/mila/x/xut/.conda/envs/rl_venv/lib/python3.10/site-packages/wandb/sdk/lib/sock_client.py", line 154, in send_server_request
    self._send_message(msg)
  File "/home/mila/x/xut/.conda/envs/rl_venv/lib/python3.10/site-packages/wandb/sdk/lib/sock_client.py", line 151, in _send_message
    self._sendall_with_error_handle(header + data)
  File "/home/mila/x/xut/.conda/envs/rl_venv/lib/python3.10/site-packages/wandb/sdk/lib/sock_client.py", line 130, in _sendall_with_error_handle
    sent = self._sock.send(data)
BrokenPipeError: [Errno 32] Broken pipe
2025-04-10 16:43:41,889 ERROR   MainThread:3628795 [redirect.py:_on_write():661] [no run ID] error in stderr callback
Traceback (most recent call last):
  File "/home/mila/x/xut/.conda/envs/rl_venv/lib/python3.10/site-packages/wandb/sdk/lib/redirect.py", line 659, in _on_write
    cb(written_data)
  File "/home/mila/x/xut/.conda/envs/rl_venv/lib/python3.10/site-packages/wandb/sdk/wandb_run.py", line 2381, in <lambda>
    lambda data: self._console_raw_callback("stderr", data),
  File "/home/mila/x/xut/.conda/envs/rl_venv/lib/python3.10/site-packages/wandb/sdk/wandb_run.py", line 387, in wrapper
    return func(self, *args, **kwargs)
  File "/home/mila/x/xut/.conda/envs/rl_venv/lib/python3.10/site-packages/wandb/sdk/wandb_run.py", line 435, in wrapper_fn
    return func(self, *args, **kwargs)
  File "/home/mila/x/xut/.conda/envs/rl_venv/lib/python3.10/site-packages/wandb/sdk/wandb_run.py", line 1518, in _console_raw_callback
    self._backend.interface.publish_output_raw(name, data)
  File "/home/mila/x/xut/.conda/envs/rl_venv/lib/python3.10/site-packages/wandb/sdk/interface/interface.py", line 761, in publish_output_raw
    self._publish_output_raw(o)
  File "/home/mila/x/xut/.conda/envs/rl_venv/lib/python3.10/site-packages/wandb/sdk/interface/interface_shared.py", line 38, in _publish_output_raw
    self._publish(rec)
  File "/home/mila/x/xut/.conda/envs/rl_venv/lib/python3.10/site-packages/wandb/sdk/interface/interface_sock.py", line 39, in _publish
    self._sock_client.send_record_publish(record)
  File "/home/mila/x/xut/.conda/envs/rl_venv/lib/python3.10/site-packages/wandb/sdk/lib/sock_client.py", line 174, in send_record_publish
    self.send_server_request(server_req)
  File "/home/mila/x/xut/.conda/envs/rl_venv/lib/python3.10/site-packages/wandb/sdk/lib/sock_client.py", line 154, in send_server_request
    self._send_message(msg)
  File "/home/mila/x/xut/.conda/envs/rl_venv/lib/python3.10/site-packages/wandb/sdk/lib/sock_client.py", line 151, in _send_message
    self._sendall_with_error_handle(header + data)
  File "/home/mila/x/xut/.conda/envs/rl_venv/lib/python3.10/site-packages/wandb/sdk/lib/sock_client.py", line 130, in _sendall_with_error_handle
    sent = self._sock.send(data)
BrokenPipeError: [Errno 32] Broken pipe
2025-04-10 16:43:41,890 ERROR   MainThread:3628795 [redirect.py:_on_write():661] [no run ID] error in stderr callback
Traceback (most recent call last):
  File "/home/mila/x/xut/.conda/envs/rl_venv/lib/python3.10/site-packages/wandb/sdk/lib/redirect.py", line 659, in _on_write
    cb(written_data)
  File "/home/mila/x/xut/.conda/envs/rl_venv/lib/python3.10/site-packages/wandb/sdk/wandb_run.py", line 2381, in <lambda>
    lambda data: self._console_raw_callback("stderr", data),
  File "/home/mila/x/xut/.conda/envs/rl_venv/lib/python3.10/site-packages/wandb/sdk/wandb_run.py", line 387, in wrapper
    return func(self, *args, **kwargs)
  File "/home/mila/x/xut/.conda/envs/rl_venv/lib/python3.10/site-packages/wandb/sdk/wandb_run.py", line 435, in wrapper_fn
    return func(self, *args, **kwargs)
  File "/home/mila/x/xut/.conda/envs/rl_venv/lib/python3.10/site-packages/wandb/sdk/wandb_run.py", line 1518, in _console_raw_callback
    self._backend.interface.publish_output_raw(name, data)
  File "/home/mila/x/xut/.conda/envs/rl_venv/lib/python3.10/site-packages/wandb/sdk/interface/interface.py", line 761, in publish_output_raw
    self._publish_output_raw(o)
  File "/home/mila/x/xut/.conda/envs/rl_venv/lib/python3.10/site-packages/wandb/sdk/interface/interface_shared.py", line 38, in _publish_output_raw
    self._publish(rec)
  File "/home/mila/x/xut/.conda/envs/rl_venv/lib/python3.10/site-packages/wandb/sdk/interface/interface_sock.py", line 39, in _publish
    self._sock_client.send_record_publish(record)
  File "/home/mila/x/xut/.conda/envs/rl_venv/lib/python3.10/site-packages/wandb/sdk/lib/sock_client.py", line 174, in send_record_publish
    self.send_server_request(server_req)
  File "/home/mila/x/xut/.conda/envs/rl_venv/lib/python3.10/site-packages/wandb/sdk/lib/sock_client.py", line 154, in send_server_request
    self._send_message(msg)
  File "/home/mila/x/xut/.conda/envs/rl_venv/lib/python3.10/site-packages/wandb/sdk/lib/sock_client.py", line 151, in _send_message
    self._sendall_with_error_handle(header + data)
  File "/home/mila/x/xut/.conda/envs/rl_venv/lib/python3.10/site-packages/wandb/sdk/lib/sock_client.py", line 130, in _sendall_with_error_handle
    sent = self._sock.send(data)
BrokenPipeError: [Errno 32] Broken pipe
2025-04-10 16:43:41,890 ERROR   MainThread:3628795 [redirect.py:_on_write():661] [no run ID] error in stderr callback
Traceback (most recent call last):
  File "/home/mila/x/xut/.conda/envs/rl_venv/lib/python3.10/site-packages/wandb/sdk/lib/redirect.py", line 659, in _on_write
    cb(written_data)
  File "/home/mila/x/xut/.conda/envs/rl_venv/lib/python3.10/site-packages/wandb/sdk/wandb_run.py", line 2381, in <lambda>
    lambda data: self._console_raw_callback("stderr", data),
  File "/home/mila/x/xut/.conda/envs/rl_venv/lib/python3.10/site-packages/wandb/sdk/wandb_run.py", line 387, in wrapper
    return func(self, *args, **kwargs)
  File "/home/mila/x/xut/.conda/envs/rl_venv/lib/python3.10/site-packages/wandb/sdk/wandb_run.py", line 435, in wrapper_fn
    return func(self, *args, **kwargs)
  File "/home/mila/x/xut/.conda/envs/rl_venv/lib/python3.10/site-packages/wandb/sdk/wandb_run.py", line 1518, in _console_raw_callback
    self._backend.interface.publish_output_raw(name, data)
  File "/home/mila/x/xut/.conda/envs/rl_venv/lib/python3.10/site-packages/wandb/sdk/interface/interface.py", line 761, in publish_output_raw
    self._publish_output_raw(o)
  File "/home/mila/x/xut/.conda/envs/rl_venv/lib/python3.10/site-packages/wandb/sdk/interface/interface_shared.py", line 38, in _publish_output_raw
    self._publish(rec)
  File "/home/mila/x/xut/.conda/envs/rl_venv/lib/python3.10/site-packages/wandb/sdk/interface/interface_sock.py", line 39, in _publish
    self._sock_client.send_record_publish(record)
  File "/home/mila/x/xut/.conda/envs/rl_venv/lib/python3.10/site-packages/wandb/sdk/lib/sock_client.py", line 174, in send_record_publish
    self.send_server_request(server_req)
  File "/home/mila/x/xut/.conda/envs/rl_venv/lib/python3.10/site-packages/wandb/sdk/lib/sock_client.py", line 154, in send_server_request
    self._send_message(msg)
  File "/home/mila/x/xut/.conda/envs/rl_venv/lib/python3.10/site-packages/wandb/sdk/lib/sock_client.py", line 151, in _send_message
    self._sendall_with_error_handle(header + data)
  File "/home/mila/x/xut/.conda/envs/rl_venv/lib/python3.10/site-packages/wandb/sdk/lib/sock_client.py", line 130, in _sendall_with_error_handle
    sent = self._sock.send(data)
BrokenPipeError: [Errno 32] Broken pipe
2025-04-10 16:43:41,891 ERROR   MainThread:3628795 [redirect.py:_on_write():661] [no run ID] error in stderr callback
Traceback (most recent call last):
  File "/home/mila/x/xut/.conda/envs/rl_venv/lib/python3.10/site-packages/wandb/sdk/lib/redirect.py", line 659, in _on_write
    cb(written_data)
  File "/home/mila/x/xut/.conda/envs/rl_venv/lib/python3.10/site-packages/wandb/sdk/wandb_run.py", line 2381, in <lambda>
    lambda data: self._console_raw_callback("stderr", data),
  File "/home/mila/x/xut/.conda/envs/rl_venv/lib/python3.10/site-packages/wandb/sdk/wandb_run.py", line 387, in wrapper
    return func(self, *args, **kwargs)
  File "/home/mila/x/xut/.conda/envs/rl_venv/lib/python3.10/site-packages/wandb/sdk/wandb_run.py", line 435, in wrapper_fn
    return func(self, *args, **kwargs)
  File "/home/mila/x/xut/.conda/envs/rl_venv/lib/python3.10/site-packages/wandb/sdk/wandb_run.py", line 1518, in _console_raw_callback
    self._backend.interface.publish_output_raw(name, data)
  File "/home/mila/x/xut/.conda/envs/rl_venv/lib/python3.10/site-packages/wandb/sdk/interface/interface.py", line 761, in publish_output_raw
    self._publish_output_raw(o)
  File "/home/mila/x/xut/.conda/envs/rl_venv/lib/python3.10/site-packages/wandb/sdk/interface/interface_shared.py", line 38, in _publish_output_raw
    self._publish(rec)
  File "/home/mila/x/xut/.conda/envs/rl_venv/lib/python3.10/site-packages/wandb/sdk/interface/interface_sock.py", line 39, in _publish
    self._sock_client.send_record_publish(record)
  File "/home/mila/x/xut/.conda/envs/rl_venv/lib/python3.10/site-packages/wandb/sdk/lib/sock_client.py", line 174, in send_record_publish
    self.send_server_request(server_req)
  File "/home/mila/x/xut/.conda/envs/rl_venv/lib/python3.10/site-packages/wandb/sdk/lib/sock_client.py", line 154, in send_server_request
    self._send_message(msg)
  File "/home/mila/x/xut/.conda/envs/rl_venv/lib/python3.10/site-packages/wandb/sdk/lib/sock_client.py", line 151, in _send_message
    self._sendall_with_error_handle(header + data)
  File "/home/mila/x/xut/.conda/envs/rl_venv/lib/python3.10/site-packages/wandb/sdk/lib/sock_client.py", line 130, in _sendall_with_error_handle
    sent = self._sock.send(data)
BrokenPipeError: [Errno 32] Broken pipe
2025-04-10 16:43:41,891 ERROR   MainThread:3628795 [redirect.py:_on_write():661] [no run ID] error in stderr callback
Traceback (most recent call last):
  File "/home/mila/x/xut/.conda/envs/rl_venv/lib/python3.10/site-packages/wandb/sdk/lib/redirect.py", line 659, in _on_write
    cb(written_data)
  File "/home/mila/x/xut/.conda/envs/rl_venv/lib/python3.10/site-packages/wandb/sdk/wandb_run.py", line 2381, in <lambda>
    lambda data: self._console_raw_callback("stderr", data),
  File "/home/mila/x/xut/.conda/envs/rl_venv/lib/python3.10/site-packages/wandb/sdk/wandb_run.py", line 387, in wrapper
    return func(self, *args, **kwargs)
  File "/home/mila/x/xut/.conda/envs/rl_venv/lib/python3.10/site-packages/wandb/sdk/wandb_run.py", line 435, in wrapper_fn
    return func(self, *args, **kwargs)
  File "/home/mila/x/xut/.conda/envs/rl_venv/lib/python3.10/site-packages/wandb/sdk/wandb_run.py", line 1518, in _console_raw_callback
    self._backend.interface.publish_output_raw(name, data)
  File "/home/mila/x/xut/.conda/envs/rl_venv/lib/python3.10/site-packages/wandb/sdk/interface/interface.py", line 761, in publish_output_raw
    self._publish_output_raw(o)
  File "/home/mila/x/xut/.conda/envs/rl_venv/lib/python3.10/site-packages/wandb/sdk/interface/interface_shared.py", line 38, in _publish_output_raw
    self._publish(rec)
  File "/home/mila/x/xut/.conda/envs/rl_venv/lib/python3.10/site-packages/wandb/sdk/interface/interface_sock.py", line 39, in _publish
    self._sock_client.send_record_publish(record)
  File "/home/mila/x/xut/.conda/envs/rl_venv/lib/python3.10/site-packages/wandb/sdk/lib/sock_client.py", line 174, in send_record_publish
    self.send_server_request(server_req)
  File "/home/mila/x/xut/.conda/envs/rl_venv/lib/python3.10/site-packages/wandb/sdk/lib/sock_client.py", line 154, in send_server_request
    self._send_message(msg)
  File "/home/mila/x/xut/.conda/envs/rl_venv/lib/python3.10/site-packages/wandb/sdk/lib/sock_client.py", line 151, in _send_message
    self._sendall_with_error_handle(header + data)
  File "/home/mila/x/xut/.conda/envs/rl_venv/lib/python3.10/site-packages/wandb/sdk/lib/sock_client.py", line 130, in _sendall_with_error_handle
    sent = self._sock.send(data)
BrokenPipeError: [Errno 32] Broken pipe
